[2025-10-02T19:49:29.544+0000] {taskinstance.py:1157} INFO - Dependencies all met for dep_context=non-requeueable deps ti=<TaskInstance: etl_tweets.extract manual__2025-10-02T19:49:25.310339+00:00 [queued]>
[2025-10-02T19:49:29.570+0000] {taskinstance.py:1157} INFO - Dependencies all met for dep_context=requeueable deps ti=<TaskInstance: etl_tweets.extract manual__2025-10-02T19:49:25.310339+00:00 [queued]>
[2025-10-02T19:49:29.571+0000] {taskinstance.py:1359} INFO - Starting attempt 1 of 1
[2025-10-02T19:49:29.603+0000] {taskinstance.py:1380} INFO - Executing <Task(PythonOperator): extract> on 2025-10-02 19:49:25.310339+00:00
[2025-10-02T19:49:29.610+0000] {standard_task_runner.py:57} INFO - Started process 411 to run task
[2025-10-02T19:49:29.615+0000] {standard_task_runner.py:84} INFO - Running: ['airflow', 'tasks', 'run', 'etl_tweets', 'extract', 'manual__2025-10-02T19:49:25.310339+00:00', '--job-id', '2', '--raw', '--subdir', 'DAGS_FOLDER/etl_tweets.py', '--cfg-path', '/tmp/tmpzyqcwe7t']
[2025-10-02T19:49:29.620+0000] {standard_task_runner.py:85} INFO - Job 2: Subtask extract
[2025-10-02T19:49:29.652+0000] {logging_mixin.py:151} WARNING - /home/airflow/.local/lib/python3.8/site-packages/airflow/settings.py:195 DeprecationWarning: The sql_alchemy_conn option in [core] has been moved to the sql_alchemy_conn option in [database] - the old setting has been used, but please update your config.
[2025-10-02T19:49:29.735+0000] {task_command.py:415} INFO - Running <TaskInstance: etl_tweets.extract manual__2025-10-02T19:49:25.310339+00:00 [running]> on host 2024c11e8fc4
[2025-10-02T19:49:29.882+0000] {taskinstance.py:1660} INFO - Exporting env vars: AIRFLOW_CTX_DAG_OWNER='airflow' AIRFLOW_CTX_DAG_ID='etl_tweets' AIRFLOW_CTX_TASK_ID='extract' AIRFLOW_CTX_EXECUTION_DATE='2025-10-02T19:49:25.310339+00:00' AIRFLOW_CTX_TRY_NUMBER='1' AIRFLOW_CTX_DAG_RUN_ID='manual__2025-10-02T19:49:25.310339+00:00'
[2025-10-02T19:49:29.888+0000] {taskinstance.py:1935} ERROR - Task failed with exception
Traceback (most recent call last):
  File "/home/airflow/.local/lib/python3.8/site-packages/airflow/operators/python.py", line 192, in execute
    return_value = self.execute_callable()
  File "/home/airflow/.local/lib/python3.8/site-packages/airflow/operators/python.py", line 209, in execute_callable
    return self.python_callable(*self.op_args, **self.op_kwargs)
  File "/opt/airflow/dags/etl_tweets.py", line 12, in extract
    df = pd.read_csv(src)
  File "/home/airflow/.local/lib/python3.8/site-packages/pandas/io/parsers/readers.py", line 912, in read_csv
    return _read(filepath_or_buffer, kwds)
  File "/home/airflow/.local/lib/python3.8/site-packages/pandas/io/parsers/readers.py", line 577, in _read
    parser = TextFileReader(filepath_or_buffer, **kwds)
  File "/home/airflow/.local/lib/python3.8/site-packages/pandas/io/parsers/readers.py", line 1407, in __init__
    self._engine = self._make_engine(f, self.engine)
  File "/home/airflow/.local/lib/python3.8/site-packages/pandas/io/parsers/readers.py", line 1661, in _make_engine
    self.handles = get_handle(
  File "/home/airflow/.local/lib/python3.8/site-packages/pandas/io/common.py", line 859, in get_handle
    handle = open(
FileNotFoundError: [Errno 2] No such file or directory: '/opt/airflow/data/tweets.csv'
[2025-10-02T19:49:29.908+0000] {taskinstance.py:1398} INFO - Marking task as FAILED. dag_id=etl_tweets, task_id=extract, execution_date=20251002T194925, start_date=20251002T194929, end_date=20251002T194929
[2025-10-02T19:49:29.932+0000] {standard_task_runner.py:104} ERROR - Failed to execute job 2 for task extract ([Errno 2] No such file or directory: '/opt/airflow/data/tweets.csv'; 411)
[2025-10-02T19:49:29.958+0000] {local_task_job_runner.py:228} INFO - Task exited with return code 1
[2025-10-02T19:49:29.997+0000] {taskinstance.py:2776} INFO - 0 downstream tasks scheduled from follow-on schedule check
