[2025-10-03T12:13:00.380+0000] {taskinstance.py:1157} INFO - Dependencies all met for dep_context=non-requeueable deps ti=<TaskInstance: etl_tweets.call manual__2025-10-03T12:12:50.660609+00:00 [queued]>
[2025-10-03T12:13:00.404+0000] {taskinstance.py:1157} INFO - Dependencies all met for dep_context=requeueable deps ti=<TaskInstance: etl_tweets.call manual__2025-10-03T12:12:50.660609+00:00 [queued]>
[2025-10-03T12:13:00.405+0000] {taskinstance.py:1359} INFO - Starting attempt 1 of 1
[2025-10-03T12:13:00.435+0000] {taskinstance.py:1380} INFO - Executing <Task(PythonOperator): call> on 2025-10-03 12:12:50.660609+00:00
[2025-10-03T12:13:00.447+0000] {standard_task_runner.py:57} INFO - Started process 276 to run task
[2025-10-03T12:13:00.455+0000] {standard_task_runner.py:84} INFO - Running: ['airflow', 'tasks', 'run', 'etl_tweets', 'call', 'manual__2025-10-03T12:12:50.660609+00:00', '--job-id', '29', '--raw', '--subdir', 'DAGS_FOLDER/etl_tweets.py', '--cfg-path', '/tmp/tmpexrg6jew']
[2025-10-03T12:13:00.459+0000] {standard_task_runner.py:85} INFO - Job 29: Subtask call
[2025-10-03T12:13:00.513+0000] {logging_mixin.py:151} WARNING - /home/airflow/.local/lib/python3.8/site-packages/airflow/settings.py:195 DeprecationWarning: The sql_alchemy_conn option in [core] has been moved to the sql_alchemy_conn option in [database] - the old setting has been used, but please update your config.
[2025-10-03T12:13:00.610+0000] {task_command.py:415} INFO - Running <TaskInstance: etl_tweets.call manual__2025-10-03T12:12:50.660609+00:00 [running]> on host 49f24dd9f1a8
[2025-10-03T12:13:00.812+0000] {taskinstance.py:1660} INFO - Exporting env vars: AIRFLOW_CTX_DAG_OWNER='airflow' AIRFLOW_CTX_DAG_ID='etl_tweets' AIRFLOW_CTX_TASK_ID='call' AIRFLOW_CTX_EXECUTION_DATE='2025-10-03T12:12:50.660609+00:00' AIRFLOW_CTX_TRY_NUMBER='1' AIRFLOW_CTX_DAG_RUN_ID='manual__2025-10-03T12:12:50.660609+00:00'
[2025-10-03T12:13:01.100+0000] {taskinstance.py:1935} ERROR - Task failed with exception
Traceback (most recent call last):
  File "/home/airflow/.local/lib/python3.8/site-packages/airflow/operators/python.py", line 192, in execute
    return_value = self.execute_callable()
  File "/home/airflow/.local/lib/python3.8/site-packages/airflow/operators/python.py", line 209, in execute_callable
    return self.python_callable(*self.op_args, **self.op_kwargs)
  File "/opt/airflow/dags/etl_tweets.py", line 50, in sentiment_global
    plt.pie(labels=labels,autopct= '%1.1f%%' ,colors=['green', 'red', 'gray'])
TypeError: pie() missing 1 required positional argument: 'x'
[2025-10-03T12:13:01.129+0000] {taskinstance.py:1398} INFO - Marking task as FAILED. dag_id=etl_tweets, task_id=call, execution_date=20251003T121250, start_date=20251003T121300, end_date=20251003T121301
[2025-10-03T12:13:01.152+0000] {standard_task_runner.py:104} ERROR - Failed to execute job 29 for task call (pie() missing 1 required positional argument: 'x'; 276)
[2025-10-03T12:13:01.171+0000] {local_task_job_runner.py:228} INFO - Task exited with return code 1
[2025-10-03T12:13:01.209+0000] {taskinstance.py:2776} INFO - 0 downstream tasks scheduled from follow-on schedule check
